[2023-11-02T08:45:12.453+0000] {taskinstance.py:1159} INFO - Dependencies all met for dep_context=non-requeueable deps ti=<TaskInstance: scraper_cryptopanic.run_scraper_task scheduled__2023-11-02T08:40:03.798353+00:00 [queued]>
[2023-11-02T08:45:12.459+0000] {taskinstance.py:1159} INFO - Dependencies all met for dep_context=requeueable deps ti=<TaskInstance: scraper_cryptopanic.run_scraper_task scheduled__2023-11-02T08:40:03.798353+00:00 [queued]>
[2023-11-02T08:45:12.459+0000] {taskinstance.py:1361} INFO - Starting attempt 1 of 2
[2023-11-02T08:45:12.470+0000] {taskinstance.py:1382} INFO - Executing <Task(DockerOperator): run_scraper_task> on 2023-11-02 08:40:03.798353+00:00
[2023-11-02T08:45:12.475+0000] {standard_task_runner.py:57} INFO - Started process 58 to run task
[2023-11-02T08:45:12.478+0000] {standard_task_runner.py:84} INFO - Running: ['***', 'tasks', 'run', 'scraper_cryptopanic', 'run_scraper_task', 'scheduled__2023-11-02T08:40:03.798353+00:00', '--job-id', '3', '--raw', '--subdir', 'DAGS_FOLDER/scraping/cryptopanic.py', '--cfg-path', '/tmp/tmpqzu39mcw']
[2023-11-02T08:45:12.480+0000] {standard_task_runner.py:85} INFO - Job 3: Subtask run_scraper_task
[2023-11-02T08:45:12.514+0000] {task_command.py:416} INFO - Running <TaskInstance: scraper_cryptopanic.run_scraper_task scheduled__2023-11-02T08:40:03.798353+00:00 [running]> on host bc7f80b804d5
[2023-11-02T08:45:12.574+0000] {taskinstance.py:1662} INFO - Exporting env vars: AIRFLOW_CTX_DAG_OWNER='***' AIRFLOW_CTX_DAG_ID='scraper_cryptopanic' AIRFLOW_CTX_TASK_ID='run_scraper_task' AIRFLOW_CTX_EXECUTION_DATE='2023-11-02T08:40:03.798353+00:00' AIRFLOW_CTX_TRY_NUMBER='1' AIRFLOW_CTX_DAG_RUN_ID='scheduled__2023-11-02T08:40:03.798353+00:00'
[2023-11-02T08:45:12.650+0000] {docker.py:470} INFO - Pulling docker image scraper:latest
[2023-11-02T08:45:14.690+0000] {taskinstance.py:1937} ERROR - Task failed with exception
Traceback (most recent call last):
  File "/home/airflow/.local/lib/python3.11/site-packages/docker/api/client.py", line 268, in _raise_for_status
    response.raise_for_status()
  File "/home/airflow/.local/lib/python3.11/site-packages/requests/models.py", line 1021, in raise_for_status
    raise HTTPError(http_error_msg, response=self)
requests.exceptions.HTTPError: 404 Client Error: Not Found for url: http+docker://localhost/v1.43/images/create?tag=latest&fromImage=scraper

The above exception was the direct cause of the following exception:

Traceback (most recent call last):
  File "/home/airflow/.local/lib/python3.11/site-packages/airflow/providers/docker/operators/docker.py", line 472, in execute
    for output in self.cli.pull(self.image, stream=True, decode=True):
                  ^^^^^^^^^^^^^^^^^^^^^^^^^^^^^^^^^^^^^^^^^^^^^^^^^^^
  File "/home/airflow/.local/lib/python3.11/site-packages/docker/api/image.py", line 429, in pull
    self._raise_for_status(response)
  File "/home/airflow/.local/lib/python3.11/site-packages/docker/api/client.py", line 270, in _raise_for_status
    raise create_api_error_from_http_exception(e) from e
          ^^^^^^^^^^^^^^^^^^^^^^^^^^^^^^^^^^^^^^^
  File "/home/airflow/.local/lib/python3.11/site-packages/docker/errors.py", line 39, in create_api_error_from_http_exception
    raise cls(e, response=response, explanation=explanation) from e
docker.errors.ImageNotFound: 404 Client Error for http+docker://localhost/v1.43/images/create?tag=latest&fromImage=scraper: Not Found ("pull access denied for scraper, repository does not exist or may require 'docker login': denied: requested access to the resource is denied")
[2023-11-02T08:45:14.750+0000] {taskinstance.py:1400} INFO - Marking task as UP_FOR_RETRY. dag_id=scraper_cryptopanic, task_id=run_scraper_task, execution_date=20231102T084003, start_date=20231102T084512, end_date=20231102T084514
[2023-11-02T08:45:14.775+0000] {standard_task_runner.py:104} ERROR - Failed to execute job 3 for task run_scraper_task (404 Client Error for http+docker://localhost/v1.43/images/create?tag=latest&fromImage=scraper: Not Found ("pull access denied for scraper, repository does not exist or may require 'docker login': denied: requested access to the resource is denied"); 58)
[2023-11-02T08:45:14.814+0000] {local_task_job_runner.py:228} INFO - Task exited with return code 1
[2023-11-02T08:45:14.851+0000] {taskinstance.py:2778} INFO - 0 downstream tasks scheduled from follow-on schedule check
