[2023-10-30T18:07:27.443+0000] {taskinstance.py:1159} INFO - Dependencies all met for dep_context=non-requeueable deps ti=<TaskInstance: scraper_cryptopanic.run_scraper_task scheduled__2023-10-30T18:02:25.925438+00:00 [queued]>
[2023-10-30T18:07:27.446+0000] {taskinstance.py:1159} INFO - Dependencies all met for dep_context=requeueable deps ti=<TaskInstance: scraper_cryptopanic.run_scraper_task scheduled__2023-10-30T18:02:25.925438+00:00 [queued]>
[2023-10-30T18:07:27.446+0000] {taskinstance.py:1361} INFO - Starting attempt 1 of 2
[2023-10-30T18:07:27.452+0000] {taskinstance.py:1382} INFO - Executing <Task(DockerOperator): run_scraper_task> on 2023-10-30 18:02:25.925438+00:00
[2023-10-30T18:07:27.455+0000] {standard_task_runner.py:57} INFO - Started process 156 to run task
[2023-10-30T18:07:27.458+0000] {standard_task_runner.py:84} INFO - Running: ['***', 'tasks', 'run', 'scraper_cryptopanic', 'run_scraper_task', 'scheduled__2023-10-30T18:02:25.925438+00:00', '--job-id', '6', '--raw', '--subdir', 'DAGS_FOLDER/scraping/cryptopanic.py', '--cfg-path', '/tmp/tmpvh1t6e2q']
[2023-10-30T18:07:27.461+0000] {standard_task_runner.py:85} INFO - Job 6: Subtask run_scraper_task
[2023-10-30T18:07:27.512+0000] {task_command.py:416} INFO - Running <TaskInstance: scraper_cryptopanic.run_scraper_task scheduled__2023-10-30T18:02:25.925438+00:00 [running]> on host 02593bcde4e0
[2023-10-30T18:07:27.554+0000] {taskinstance.py:1662} INFO - Exporting env vars: AIRFLOW_CTX_DAG_OWNER='***' AIRFLOW_CTX_DAG_ID='scraper_cryptopanic' AIRFLOW_CTX_TASK_ID='run_scraper_task' AIRFLOW_CTX_EXECUTION_DATE='2023-10-30T18:02:25.925438+00:00' AIRFLOW_CTX_TRY_NUMBER='1' AIRFLOW_CTX_DAG_RUN_ID='scheduled__2023-10-30T18:02:25.925438+00:00'
[2023-10-30T18:07:27.559+0000] {taskinstance.py:1937} ERROR - Task failed with exception
Traceback (most recent call last):
  File "/home/airflow/.local/lib/python3.11/site-packages/urllib3/connectionpool.py", line 714, in urlopen
    httplib_response = self._make_request(
                       ^^^^^^^^^^^^^^^^^^^
  File "/home/airflow/.local/lib/python3.11/site-packages/urllib3/connectionpool.py", line 415, in _make_request
    conn.request(method, url, **httplib_request_kw)
  File "/home/airflow/.local/lib/python3.11/site-packages/urllib3/connection.py", line 244, in request
    super(HTTPConnection, self).request(method, url, body=body, headers=headers)
  File "/usr/local/lib/python3.11/http/client.py", line 1286, in request
    self._send_request(method, url, body, headers, encode_chunked)
  File "/usr/local/lib/python3.11/http/client.py", line 1332, in _send_request
    self.endheaders(body, encode_chunked=encode_chunked)
  File "/usr/local/lib/python3.11/http/client.py", line 1281, in endheaders
    self._send_output(message_body, encode_chunked=encode_chunked)
  File "/usr/local/lib/python3.11/http/client.py", line 1041, in _send_output
    self.send(msg)
  File "/usr/local/lib/python3.11/http/client.py", line 979, in send
    self.connect()
  File "/home/airflow/.local/lib/python3.11/site-packages/docker/transport/unixconn.py", line 27, in connect
    sock.connect(self.unix_socket)
FileNotFoundError: [Errno 2] No such file or directory

During handling of the above exception, another exception occurred:

Traceback (most recent call last):
  File "/home/airflow/.local/lib/python3.11/site-packages/requests/adapters.py", line 486, in send
    resp = conn.urlopen(
           ^^^^^^^^^^^^^
  File "/home/airflow/.local/lib/python3.11/site-packages/urllib3/connectionpool.py", line 798, in urlopen
    retries = retries.increment(
              ^^^^^^^^^^^^^^^^^^
  File "/home/airflow/.local/lib/python3.11/site-packages/urllib3/util/retry.py", line 550, in increment
    raise six.reraise(type(error), error, _stacktrace)
          ^^^^^^^^^^^^^^^^^^^^^^^^^^^^^^^^^^^^^^^^^^^^
  File "/home/airflow/.local/lib/python3.11/site-packages/urllib3/packages/six.py", line 769, in reraise
    raise value.with_traceback(tb)
  File "/home/airflow/.local/lib/python3.11/site-packages/urllib3/connectionpool.py", line 714, in urlopen
    httplib_response = self._make_request(
                       ^^^^^^^^^^^^^^^^^^^
  File "/home/airflow/.local/lib/python3.11/site-packages/urllib3/connectionpool.py", line 415, in _make_request
    conn.request(method, url, **httplib_request_kw)
  File "/home/airflow/.local/lib/python3.11/site-packages/urllib3/connection.py", line 244, in request
    super(HTTPConnection, self).request(method, url, body=body, headers=headers)
  File "/usr/local/lib/python3.11/http/client.py", line 1286, in request
    self._send_request(method, url, body, headers, encode_chunked)
  File "/usr/local/lib/python3.11/http/client.py", line 1332, in _send_request
    self.endheaders(body, encode_chunked=encode_chunked)
  File "/usr/local/lib/python3.11/http/client.py", line 1281, in endheaders
    self._send_output(message_body, encode_chunked=encode_chunked)
  File "/usr/local/lib/python3.11/http/client.py", line 1041, in _send_output
    self.send(msg)
  File "/usr/local/lib/python3.11/http/client.py", line 979, in send
    self.connect()
  File "/home/airflow/.local/lib/python3.11/site-packages/docker/transport/unixconn.py", line 27, in connect
    sock.connect(self.unix_socket)
urllib3.exceptions.ProtocolError: ('Connection aborted.', FileNotFoundError(2, 'No such file or directory'))

During handling of the above exception, another exception occurred:

Traceback (most recent call last):
  File "/home/airflow/.local/lib/python3.11/site-packages/docker/api/client.py", line 214, in _retrieve_server_version
    return self.version(api_version=False)["ApiVersion"]
           ^^^^^^^^^^^^^^^^^^^^^^^^^^^^^^^
  File "/home/airflow/.local/lib/python3.11/site-packages/docker/api/daemon.py", line 181, in version
    return self._result(self._get(url), json=True)
                        ^^^^^^^^^^^^^^
  File "/home/airflow/.local/lib/python3.11/site-packages/docker/utils/decorators.py", line 46, in inner
    return f(self, *args, **kwargs)
           ^^^^^^^^^^^^^^^^^^^^^^^^
  File "/home/airflow/.local/lib/python3.11/site-packages/docker/api/client.py", line 237, in _get
    return self.get(url, **self._set_request_timeout(kwargs))
           ^^^^^^^^^^^^^^^^^^^^^^^^^^^^^^^^^^^^^^^^^^^^^^^^^^
  File "/home/airflow/.local/lib/python3.11/site-packages/requests/sessions.py", line 602, in get
    return self.request("GET", url, **kwargs)
           ^^^^^^^^^^^^^^^^^^^^^^^^^^^^^^^^^^
  File "/home/airflow/.local/lib/python3.11/site-packages/requests/sessions.py", line 589, in request
    resp = self.send(prep, **send_kwargs)
           ^^^^^^^^^^^^^^^^^^^^^^^^^^^^^^
  File "/home/airflow/.local/lib/python3.11/site-packages/requests/sessions.py", line 703, in send
    r = adapter.send(request, **kwargs)
        ^^^^^^^^^^^^^^^^^^^^^^^^^^^^^^^
  File "/home/airflow/.local/lib/python3.11/site-packages/requests/adapters.py", line 501, in send
    raise ConnectionError(err, request=request)
requests.exceptions.ConnectionError: ('Connection aborted.', FileNotFoundError(2, 'No such file or directory'))

During handling of the above exception, another exception occurred:

Traceback (most recent call last):
  File "/home/airflow/.local/lib/python3.11/site-packages/airflow/providers/docker/operators/docker.py", line 469, in execute
    if self.force_pull or not self.cli.images(name=self.image):
                              ^^^^^^^^
  File "/home/airflow/.local/lib/python3.11/site-packages/airflow/providers/docker/operators/docker.py", line 339, in cli
    return self.hook.api_client
           ^^^^^^^^^^^^^^^^^^^^
  File "/usr/local/lib/python3.11/functools.py", line 1001, in __get__
    val = self.func(instance)
          ^^^^^^^^^^^^^^^^^^^
  File "/home/airflow/.local/lib/python3.11/site-packages/airflow/providers/docker/hooks/docker.py", line 120, in api_client
    client = APIClient(
             ^^^^^^^^^^
  File "/home/airflow/.local/lib/python3.11/site-packages/docker/api/client.py", line 197, in __init__
    self._version = self._retrieve_server_version()
                    ^^^^^^^^^^^^^^^^^^^^^^^^^^^^^^^
  File "/home/airflow/.local/lib/python3.11/site-packages/docker/api/client.py", line 221, in _retrieve_server_version
    raise DockerException(
docker.errors.DockerException: Error while fetching server API version: ('Connection aborted.', FileNotFoundError(2, 'No such file or directory'))
[2023-10-30T18:07:27.573+0000] {taskinstance.py:1400} INFO - Marking task as UP_FOR_RETRY. dag_id=scraper_cryptopanic, task_id=run_scraper_task, execution_date=20231030T180225, start_date=20231030T180727, end_date=20231030T180727
[2023-10-30T18:07:27.578+0000] {standard_task_runner.py:104} ERROR - Failed to execute job 6 for task run_scraper_task (Error while fetching server API version: ('Connection aborted.', FileNotFoundError(2, 'No such file or directory')); 156)
[2023-10-30T18:07:27.612+0000] {local_task_job_runner.py:228} INFO - Task exited with return code 1
[2023-10-30T18:07:27.622+0000] {taskinstance.py:2778} INFO - 0 downstream tasks scheduled from follow-on schedule check
